[2025-04-17T21:17:35.368+0000] {local_task_job_runner.py:120} INFO - ::group::Pre task execution logs
[2025-04-17T21:17:35.419+0000] {taskinstance.py:2076} INFO - Dependencies all met for dep_context=non-requeueable deps ti=<TaskInstance: data_pipeline_demo.download_data manual__2025-04-17T21:17:33.510174+00:00 [queued]>
[2025-04-17T21:17:35.428+0000] {taskinstance.py:2076} INFO - Dependencies all met for dep_context=requeueable deps ti=<TaskInstance: data_pipeline_demo.download_data manual__2025-04-17T21:17:33.510174+00:00 [queued]>
[2025-04-17T21:17:35.432+0000] {taskinstance.py:2306} INFO - Starting attempt 1 of 1
[2025-04-17T21:17:35.453+0000] {taskinstance.py:2330} INFO - Executing <Task(PythonOperator): download_data> on 2025-04-17 21:17:33.510174+00:00
[2025-04-17T21:17:35.458+0000] {standard_task_runner.py:63} INFO - Started process 753 to run task
[2025-04-17T21:17:35.463+0000] {standard_task_runner.py:90} INFO - Running: ['***', 'tasks', 'run', 'data_pipeline_demo', 'download_data', 'manual__2025-04-17T21:17:33.510174+00:00', '--job-id', '2', '--raw', '--subdir', 'DAGS_FOLDER/pipeline.py', '--cfg-path', '/tmp/tmp6nskslyk']
[2025-04-17T21:17:35.467+0000] {standard_task_runner.py:91} INFO - Job 2: Subtask download_data
[2025-04-17T21:17:35.511+0000] {logging_mixin.py:188} WARNING - /home/***/.local/lib/python3.10/site-packages/***/settings.py:195 DeprecationWarning: The sql_alchemy_conn option in [core] has been moved to the sql_alchemy_conn option in [database] - the old setting has been used, but please update your config.
[2025-04-17T21:17:35.556+0000] {task_command.py:426} INFO - Running <TaskInstance: data_pipeline_demo.download_data manual__2025-04-17T21:17:33.510174+00:00 [running]> on host b3f0d5cbc6df
[2025-04-17T21:17:35.708+0000] {taskinstance.py:2648} INFO - Exporting env vars: AIRFLOW_CTX_DAG_OWNER='***' AIRFLOW_CTX_DAG_ID='data_pipeline_demo' AIRFLOW_CTX_TASK_ID='download_data' AIRFLOW_CTX_EXECUTION_DATE='2025-04-17T21:17:33.510174+00:00' AIRFLOW_CTX_TRY_NUMBER='1' AIRFLOW_CTX_DAG_RUN_ID='manual__2025-04-17T21:17:33.510174+00:00'
[2025-04-17T21:17:35.710+0000] {taskinstance.py:430} INFO - ::endgroup::
[2025-04-17T21:17:36.617+0000] {taskinstance.py:441} INFO - ::group::Post task execution logs
[2025-04-17T21:17:36.618+0000] {taskinstance.py:2905} ERROR - Task failed with exception
Traceback (most recent call last):
  File "/home/airflow/.local/lib/python3.10/site-packages/airflow/models/taskinstance.py", line 465, in _execute_task
    result = _execute_callable(context=context, **execute_callable_kwargs)
  File "/home/airflow/.local/lib/python3.10/site-packages/airflow/models/taskinstance.py", line 432, in _execute_callable
    return execute_callable(context=context, **execute_callable_kwargs)
  File "/home/airflow/.local/lib/python3.10/site-packages/airflow/models/baseoperator.py", line 400, in wrapper
    return func(self, *args, **kwargs)
  File "/home/airflow/.local/lib/python3.10/site-packages/airflow/operators/python.py", line 235, in execute
    return_value = self.execute_callable()
  File "/home/airflow/.local/lib/python3.10/site-packages/airflow/operators/python.py", line 252, in execute_callable
    return self.python_callable(*self.op_args, **self.op_kwargs)
  File "/opt/airflow/dags/pipeline.py", line 12, in download_data
    with open(LOCAL_PATH, 'wb') as f:
FileNotFoundError: [Errno 2] No such file or directory: '/data/winequallity.csv'
[2025-04-17T21:17:36.638+0000] {taskinstance.py:1206} INFO - Marking task as FAILED. dag_id=data_pipeline_demo, task_id=download_data, run_id=manual__2025-04-17T21:17:33.510174+00:00, execution_date=20250417T211733, start_date=20250417T211735, end_date=20250417T211736
[2025-04-17T21:17:36.660+0000] {standard_task_runner.py:110} ERROR - Failed to execute job 2 for task download_data ([Errno 2] No such file or directory: '/data/winequallity.csv'; 753)
[2025-04-17T21:17:36.687+0000] {local_task_job_runner.py:240} INFO - Task exited with return code 1
[2025-04-17T21:17:36.700+0000] {local_task_job_runner.py:222} INFO - ::endgroup::
